2022-03-20 19:19:57 ERROR Traceback (most recent call last):
  File "C:\ProgramData\Anaconda3\lib\site-packages\wandb\cli\cli.py", line 86, in wrapper
    return func(*args, **kwargs)
  File "C:\ProgramData\Anaconda3\lib\site-packages\wandb\cli\cli.py", line 235, in login
    wandb.login(relogin=relogin, key=key, anonymous=anon_mode, host=host, force=True)
  File "C:\ProgramData\Anaconda3\lib\site-packages\wandb\sdk\wandb_login.py", line 76, in login
    configured = _login(**kwargs)
  File "C:\ProgramData\Anaconda3\lib\site-packages\wandb\sdk\wandb_login.py", line 284, in _login
    wlogin.prompt_api_key()
  File "C:\ProgramData\Anaconda3\lib\site-packages\wandb\sdk\wandb_login.py", line 219, in prompt_api_key
    raise UsageError("api_key not configured (no-tty). call " + directive)
wandb.errors.UsageError: api_key not configured (no-tty). call wandb login [your_api_key]

